[2024-05-14 01:16:41,883] 1753 asyncio - ERROR - Exception in callback BaseAsyncIOLoop._handle_events(15, 1)
handle: <Handle BaseAsyncIOLoop._handle_events(15, 1)>
Traceback (most recent call last):
  File "/Users/test/MCQGenerator/env/lib/python3.9/asyncio/events.py", line 80, in _run
    self._context.run(self._callback, *self._args)
  File "/Users/test/MCQGenerator/env/lib/python3.9/site-packages/tornado/platform/asyncio.py", line 192, in _handle_events
    handler_func(fileobj, events)
  File "/Users/test/MCQGenerator/env/lib/python3.9/site-packages/tornado/iostream.py", line 721, in _handle_events
    self.io_loop.update_handler(self.fileno(), self._state)
  File "/Users/test/MCQGenerator/env/lib/python3.9/site-packages/tornado/platform/asyncio.py", line 167, in update_handler
    self.selector_loop.remove_reader(fd)
  File "/Users/test/MCQGenerator/env/lib/python3.9/asyncio/selector_events.py", line 336, in remove_reader
    return self._remove_reader(fd)
  File "/Users/test/MCQGenerator/env/lib/python3.9/asyncio/selector_events.py", line 279, in _remove_reader
    self._selector.unregister(fd)
  File "/Users/test/MCQGenerator/env/lib/python3.9/selectors.py", line 539, in unregister
    self._selector.control([kev], 0, 0)
TypeError: changelist must be an iterable of select.kevent objects
